## Tathya-UAT Error Patterns

| Error Case Description                                                  | Error Message                                                                                                                                                                                                                                                                                                                                                                                                                                                                                                                     | Prepared Regex                                                                                                                                                                                                                        |
|---------------------------------------------------------------------------|-----------------------------------------------------------------------------------------------------------------------------------------------------------------------------------------------------------------------------------------------------------------------------------------------------------------------------------------------------------------------------------------------------------------------------------------------------------------------------------------------------------------------------------|----------------------------------------------------------------------------------------------------------------------------------------------------------------------------------------------------------------------------------------|
| In case of Solr URI wrong configured this error will come                 | [SupersetError(message='(builtins.NoneType) None\n[SQL: Error 404 (Not Found) in response to GET to https://search-uat.hotwax.io:8983/solr/dev-oms-instance1Details/sql?stmt=SELECT+1+FROM+%28values%281%29%29]\n(Background on this error at: https://sqlalche.me/e/14/dbapi)', error_type=<SupersetErrorType.GENERIC_DB_ENGINE_ERROR: 'GENERIC_DB_ENGINE_ERROR'>, level=<ErrorLevel.ERROR: 'error'>, extra={'engine_name': 'Apache Solr', 'issue_codes': [{'code': 1002, 'message': 'Issue 1002 - The database returned an unexpected error.'}]})) | Chained Regex : <br>superset.exceptions.SupersetErrorsException.*<br>SupersetError\(message=["']\(builtins\.NoneType\) None\\n\[SQL: .*<br>Grafana Regex:<br>{job=""tathya-uat.hotwax.io""} |~ `superset.exceptions.SupersetErrorsException.*` |~ `SupersetError\(message=["']\(builtins\.NoneType\) None\\n\[SQL: .*` |
| In case of krewe/instance oms host not reached got this error            | MySQLdb._exceptions.OperationalError: (2002                                                                                                                                                                                                                                                                                                                                                                                                                                                                                       | Regex: <br>MySQLdb\._exceptions\.OperationalError: \(2002, ""Can't connect to server on .*<br>Grafana Regex:<br>{job=""tathya-uat.hotwax.io""} |~ `MySQLdb\._exceptions\.OperationalError: \(2002, ""Can't connect to server on .*`                |
| In case if Database password changed then this error came                | sqlalchemy.exc.DBAPIError: (builtins.NoneType) None\n[SQL: (MySQLdb._exceptions.OperationalError) (1044, ""Access denied for user 'kreweoms'@'%' to database 'kreweoms1'"")\n(Background on this error at: https://sqlalche.me/e/14/e3q8)]\n(Background on this error at: https://sqlalche.me/e/14/dbapi)\n\nThe above exception was the direct cause of the following exception:\n\nTraceback (most recent call last):\n File "/usr/local/lib/python3.9/site-packages/flask/app.py", line 1823, in full_dispatch_request\n rv = self.dispatch_request()\n File "/usr/local/lib/python3.9/site-packages/flask/app.py", line 1799, in dispatch_request\n return self.ensure_sync(self.view_functions[rule.endpoint])(**view_args)\n File "/usr/local/lib/python3.9/site-packages/flask_appbuilder/security/decorators.py", line 95, in wraps\n return f(self, *args, **kwargs)\n File "/app/superset/views/base_api.py", line 127, in wraps\n raise ex\n File "/app/superset/views/base_api.py", line 121, in wraps\n duration, response = time_function(f, self, *args, **kwargs)\n File "/app/superset/utils/core.py", line 1526, in time_function\n response = func(*args, **kwargs)\n File "/app/superset/utils/log.py", line 255, in wrapper\n value = f(*args, **kwargs)\n File "/app/superset/views/base_api.py", line 93, in wraps\n return f(self, *args, **kwargs)\n File "/app/superset/databases/api.py", line 908, in test_connection\n TestConnectionDatabaseCommand(item).run()\n File "/app/superset/databases/commands/test_connection.py", line 192, in run\n raise SupersetErrorsException(errors) from ex\nsuperset.exceptions.SupersetErrorsException: [SupersetError(message='Either the username 'kreweoms' or the password is incorrect.', error_type=<SupersetErrorType.CONNECTION_ACCESS_DENIED_ERROR: 'CONNECTION_ACCESS_DENIED_ERROR'>, level=<ErrorLevel.ERROR: 'error'>, extra={'invalid': ['username', 'password'], 'engine_name': 'MySQL', 'issue_codes': [{'code': 1014, 'message': 'Issue 1014 - Either the username or the password is wrong.'}, {'code': 1015, 'message': 'Issue 1015 - Either the database is spelled incorrectly or does not exist.'}]})] | Chained Regex : <br>superset.exceptions.SupersetErrorsException.*<br>.*SupersetError\(message=["']Either the username.*<br>Grafana Regex:<br>{job=""tathya-uat.hotwax.io""} |~ `superset.exceptions.SupersetErrorsException.*` |~ `.*SupersetError\(message=["']Either the username.*`                                                                                                                                                                                                       |
| When someone has the chart on dashboard but doesn't have access...       | In this no error captured in superset.log file                                                                                                                                                                                                                                                                                                                                                                                                                                                                                    | -                                                                                                                                                                                                                                      |
| DNS like of error                                                        | Error creating for this not possible for me                                                                                                                                                                                                                                                                                                                                                                                                                                                                                      | needs system infra-help                                                                                                                                                                                                               |
| Report execution failed error                                            | Not possible as reports error not logged in superset.log file it is directly goes into reports-logs table inside superset                                                                                                                                                                                                                                                                                                                                                      | -                                                                                                                                                                                                                                      |
| This error came because of wrong host which is not reachable...          | "2/29/2024 18:01:10 (Background on this error at: https://sqlalche.me/e/14/e3q8)                          superset.exceptions.SupersetGenericDBErrorException: (1054, ""Unknown column 'vr.description' in 'field list'"")                              2024-02-29 18:37:47        raise SupersetGenericDBErrorException(message=str(ex)) from ex                              2024-02-29 18:37:47        SupersetErrorException                              2024-02-29 17:47:44        HTTPException superset.exceptions.SupersetGenericDBErrorException: (1054, ""Unknown column 'vr.description' in 'field list'"")                                               MySQLdb._exceptions.OperationalError: (1054, ""Unknown column 'vr.description' in 'field list'"")                              2024-02-29 18:38:04        raise cls.get_dbapi_mapped_exception(ex) from ex                              2024-02-29 18:37:47        superset.exceptions.SupersetGenericDBErrorException: (1054, ""Unknown column 'vr.description' in 'field list'"")                              2024-02-29 18:37:47        The above exception was the direct cause of the following exception:                               2024-02-29 18:37:47        MySQLdb._exceptions.OperationalError: (1054, ""Unknown column 'vr.description' in 'field list'"")                              2024-02-29 18:37:47        raise cls.get_dbapi_mapped_exception(ex) from ex                              2024-02-29 18:15:10        sqlalchemy.exc.OperationalError: (MySQLdb._exceptions.OperationalError) (2002, ""Can't connect to server on '54.163.241.158' (115)"")                              2024-02-29 18:15:10        raise exception                              2024-02-29 18:15:10        raise exception                              2024-02-29 18:15:10        File ""/usr/local/lib/python3.9/site-packages/sqlalchemy/engine/base.py"", line 2117, in _handle_dbapi_exception_noconnection                              2024-02-29 18:15:10        Connection._handle_dbapi_exception_noconnection(                              2024-02-29 18:15:10        The above exception was the direct cause of the following exception:                              2024-02-29 18:15:10        MySQLdb._exceptions.OperationalError: (2002, ""Can't connect to server on '54.163.241.158' (115)"")                              2024-02-29 18:15:10        raise exception                              2024-02-29 18:12:12        sqlalchemy.exc.OperationalError: (MySQLdb._exceptions.OperationalError) (2002, ""Can't connect to server on '54.163.241.158' (115)"")                              2024-02-29 18:12:12        raise exception                              2024-02-29 18:12:12        raise exception                              2024-02-29 18:12:12        File ""/usr/local/lib/python3.9/site-packages/sqlalchemy/engine/base.py"", line 2117, in _handle_dbapi_exception_noconnection                              2024-02-29 18:12:12        Connection._handle_dbapi_exception_noconnection(                              2024-02-29 18:12:12        The above exception was the direct cause of the following exception:                              2024-02-29 18:12:12        MySQLdb._exceptions.OperationalError: (2002, ""Can't connect to server on '54.163.241.158' (115)"")                              2024-02-29 18:12:12        raise exception                              2024-02-29 18:05:10        sqlalchemy.exc.OperationalError: (MySQLdb._exceptions.OperationalError) (2002, ""Can't connect to server on '54.163.241.158' (115)"")                              2024-02-29 18:05:10        raise exception                              2024-02-29 18:05:10        raise exception                              2024-02-29 18:05:10        File ""/usr/local/lib/python3.9/site-packages/sqlalchemy/engine/base.py"", line 2117, in _handle_dbapi_exception_noconnection                              2024-02-29 18:05:10        Connection._handle_dbapi_exception_noconnection(                              2024-02-29 18:05:10        The above exception was the direct cause of the following exception:                              2024-02-29 18:05:10        MySQLdb._exceptions.OperationalError: (2002, ""Can't connect to server on '54.163.241.158' (115)"")                              2024-02-29 18:05:10        raise exception                              2024-02-29 18:01:10        sqlalchemy.exc.OperationalError: (MySQLdb._exceptions.OperationalError) (2002, ""Can't connect to server on '54.163.241.158' (115)"")                              2024-02-29 18:01:10        raise exception                              2024-02-29 18:01:10        raise exception                              2024-02-29 18:01:10        File ""/usr/local/lib/python3.9/site-packages/sqlalchemy/engine/base.py"", line 2117, in _handle_dbapi_exception_noconnection                              2024-02-29 18:01:10        Connection._handle_dbapi_exception_noconnection(                              2024-02-29 18:01:10        The above exception was the direct cause of the following exception:                              2024-02-29 18:01:10        MySQLdb._exceptions.OperationalError: (2002, ""Can't connect to server on '54.163.241.158' (115)"")                              2024-02-29 18:01:10        raise exception                              2024-02-29 17:48:46        MySQLdb._exceptions.OperationalError: (1054, ""Unknown column 'NetSuite Product ID' in 'field list'"")                              2024-02-29 17:48:46        raise cls.get_dbapi_mapped_exception(ex) from ex                              2024-02-29 17:47:44        werkzeug.exceptions.NotFound: 404 Not Found: The requested URL was not found on the server. If you entered the URL manually please check your spelling and try again.                              2024-02-29 17:47:44        raise request.routing_exception # type: ignore                              2024-02-29 17:47:44        File ""/usr/local/lib/python3.9/site-packages/flask/app.py"", line 1770, in raise_routing_exception                              2024-02-29 17:47:44        self.raise_routing_exception(req) " |                                                                                                                                                                                                                                                                                            |
| Repeated of 2nd one with different form                                   | superset.exceptions.SupersetErrorsException: [     SupersetError(         message='(MySQLdb._exceptions.OperationalError) (2002, ""Can't connect to server on '54.163.241.158' (115)"")\n(Background on this error at: https://sqlalche.me/e/14/e3q8)',         error_type=<SupersetErrorType.GENERIC_DB_ENGINE_ERROR: 'GENERIC_DB_ENGINE_ERROR'>,         level=<ErrorLevel.ERROR: 'error'>,         extra={             'engine_name': 'MySQL',             'issue_codes': [                 {'code': 1002, 'message': 'Issue 1002 - The database returned an unexpected error.'}             ]         }     ) ] |                                                                                                                                                                                                                                                                                                                                                     |
| Repeated of 3rd one with different form: This error looged because...   | superset.exceptions.SupersetErrorsException: [SupersetError(message='Either the username ""kreweom"" or the password is incorrect.', error_type=<SupersetErrorType.CONNECTION_ACCESS_DENIED_ERROR: 'CONNECTION_ACCESS_DENIED_ERROR'>, level=<ErrorLevel.ERROR: 'error'>, extra={'invalid': ['username', 'password'], 'engine_name': 'MySQL', 'issue_codes': [{'code': 1014, 'message': 'Issue 1014 - Either the username or the password is wrong.'}, {'code': 1015, 'message': 'Issue 1015 - Either the database is spelled incorrectly or does not exist.'}]})] |                                                                                                                                                                                                                                                                                                                                                     |
